<?xml version="1.0"?>

<robot name="myfirst">

<material name="blue">
  <color rgba="0 0 0.8 1"/>
</material>
<material name="black">
  <color rgba="0 0 0 1"/>
</material>
<material name="wite">
  <color rgba="1 1 1 1"/>
</material>
  <link name="base_link">
    <visual>
      <geometry>
        <cylinder length="0.6" radius="0.2"/>
      </geometry>
      <material name="blue"/>
    </visual>
    <collision>
      <geometry>
        <cylinder length="0.6" radius="0.2"/>
      </geometry>
    </collision>
    <inertial>
      <mass value="10"/>
      <inertia ixx="1e-3" ixy="0.0" ixz="0.0" iyy="1e-3" iyz="0.0" izz="1e-3"/>
    </inertial>
  </link>
  <link name= "right_leg">
    <visual>
      <geometry>
        <box size= "0.6 0.1 0.2"/>
      </geometry>
      <origin rpy="0 1.57075 0" xyz="0 0 -0.3"/>
      <material name="wite"/>
    </visual>
    <collision>
      <geometry>
        <box size="0.6 0.1 0.2"/>
      </geometry>
      <origin rpy="0 1.57075 0" xyz="0 0 -0.3"/>
    </collision>
    <inertial>
      <mass value="10"/>
      <inertia ixx="1e-3" ixy="0.0" ixz="0.0" iyy="1e-3" iyz="0.0" izz="1e-3"/>
    </inertial>
  </link>
  <joint name= "base_link_right_leg" type="fixed">
    <parent link="base_link"/>
    <child link="right_leg"/>
    <origin xyz="0 -0.25 0.25"/>
  </joint> 

<!-- base right-->
  <link name="base_right">
    <visual>
        <geometry>
            <box size="0.4 0.1 0.1"/>
        </geometry>
        <material name="wite"/>
    </visual>
    <collision>
      <geometry>
        <box size="0.4 0.1 0.1"/>
      </geometry>
    </collision>
    <inertial>
      <mass value="10"/>
      <inertia ixx="1e-3" ixy="0.0" ixz="0.0" iyy="1e-3" iyz="0.0" izz="1e-3"/>
    </inertial>
  </link>
  <joint name="base_right_to_leg_right" type="fixed">
    <parent link="right_leg"/>
    <child link="base_right"/>
    <origin xyz="0 0 -0.6"/>
  </joint>
  <link name="wheel_right_front">
    <visual>
        <geometry>
            <cylinder length="0.1" radius="0.035"/>
        </geometry>
        <origin rpy="1.57075 0 0" xyz="0 0 0"/>
        <material name="black"/>
    </visual>
    <collision>
        <geometry>
            <cylinder length="0.1" radius="0.035"/>
        </geometry>
        <origin rpy="1.57075 0 0" xyz="0 0 0"/>
    </collision>
    <inertial>
      <mass value="1"/>
      <inertia ixx="1e-3" ixy="0.0" ixz="0.0" iyy="1e-3" iyz="0.0" izz="1e-3" />
    </inertial>
  </link>
  <joint name="base_right_wheel_right_front" type="continuous">
    <axis rpy="0 0 0" xyz="0 1 0"/>
    <parent link="base_right"/>
    <child link="wheel_right_front"/>
    <origin rpy="0 0 0" xyz="0.1333 0 -0.05"/>
  </joint>
  <link name="wheel_right_back">
    <visual>
        <geometry>
            <cylinder length="0.1" radius="0.035"/>
        </geometry>
        <origin rpy="1.57075 0 0" xyz="0 0 0"/>
        <material name="black"/>
    </visual>
    <collision>
        <geometry>
            <cylinder length="0.1" radius="0.035"/>
        </geometry>
        <origin rpy="1.57075 0 0" xyz="0 0 0"/>
    </collision>
    <inertial>
      <mass value="1"/>
      <inertia ixx="1e-3" ixy="0.0" ixz="0.0" iyy="1e-3" iyz="0.0" izz="1e-3" />
    </inertial>
  </link>
  <joint name="base_right_wheel_right_back" type="continuous">
    <axis rpy="0 0 0" xyz="0 1 0"/>
    <parent link="base_right"/>
    <child link="wheel_right_back"/>
    <origin rpy="0 0 0" xyz="-0.1333 0 -0.05"/>
  </joint>
  <!-- base left-->
  <link name= "left_leg">
    <visual>
      <geometry>
        <box size= "0.6 0.1 0.2"/>
      </geometry>
      <origin rpy="0 1.57075 0" xyz="0 0 -0.3"/>
      <material name="wite"/>
    </visual>
    <collision>
      <geometry>
        <box size= "0.6 0.1 0.2"/>
      </geometry>
      <origin rpy="0 1.57075 0" xyz="0 0 -0.3"/>    
    </collision>
    <inertial>
      <mass value="10"/>
      <inertia ixx="1e-3" ixy="0.0" ixz="0.0" iyy="1e-3" iyz="0.0" izz="1e-3" />
    </inertial>
  </link>

  <joint name= "base_link_left_leg" type="fixed">
    <parent link="base_link"/>
    <child link="left_leg"/>
    <origin xyz="0 0.25 0.25"/>
  </joint>
  <link name="base_left">
    <visual>
        <geometry>
            <box size="0.4 0.1 0.1"/>
        </geometry>
        <material name="wite"/>
    </visual>
    <collision>
        <geometry>
            <box size="0.4 0.1 0.1"/>
        </geometry>
    </collision>
    <inertial>
      <mass value="10"/>
      <inertia ixx="1e-3" ixy="0.0" ixz="0.0" iyy="1e-3" iyz="0.0" izz="1e-3"/>
    </inertial>
  </link>
  <joint name="base_left_to_leg_left" type="fixed">
    <parent link="left_leg"/>
    <child link="base_left"/>
    <origin xyz="0 0 -0.6"/>
  </joint>
  <link name="wheel_left_front">
    <visual>
        <geometry>
            <cylinder length="0.1" radius="0.035"/>
        </geometry>
        <origin rpy="1.57075 0 0" xyz="0 0 0"/>
        <material name="black"/>
    </visual>
    <collision>
        <geometry>
            <cylinder length="0.1" radius="0.035"/>
        </geometry>
        <origin rpy="1.57075 0 0" xyz="0 0 0"/>  
    </collision>
    <inertial>
      <mass value="1"/>
      <inertia ixx="1e-3" ixy="0.0" ixz="0.0" iyy="1e-3" iyz="0.0" izz="1e-3"/>
    </inertial>
  </link>
  <joint name="base_left_wheel_left_front" type="continuous">
    <axis rpy="0 0 0" xyz="0 1 0"/>
    <parent link="base_left"/>
    <child link="wheel_left_front"/>
    <origin rpy="0 0 0" xyz="0.1333 0 -0.05"/>
  </joint>
  <link name="wheel_left_back">
    <visual>
        <geometry>
            <cylinder length="0.1" radius="0.035"/>
        </geometry>
        <origin rpy="1.57075 0 0" xyz="0 0 0"/>
        <material name="black"/>
    </visual>
    <collision>
        <geometry>
            <cylinder length="0.1" radius="0.035"/>
        </geometry>
        <origin rpy="1.57075 0 0" xyz="0 0 0"/>   
    </collision>
    <inertial>
      <mass value="1"/>
      <inertia ixx="1e-3" ixy="0.0" ixz="0.0" iyy="1e-3" iyz="0.0" izz="1e-3"/>
    </inertial>
  </link>
  <joint name="base_left_wheel_left_back" type="continuous">
    <axis rpy="0 0 0" xyz="0 1 0"/>
    <parent link="base_left"/>
    <child link="wheel_left_back"/>
    <origin rpy="0 0 0" xyz="-0.1333 0 -0.05"/>
  </joint>
  <link name="gripper_pole">
    <visual>
        <geometry>
            <cylinder length="0.2" radius="0.01"/>
        </geometry>
        <origin rpy="0 1.57075 0" xyz="0.1 0 0"/>
        <material name="wite"/>
    </visual>
    <collision>
        <geometry>
            <cylinder length="0.2" radius="0.01"/>
        </geometry>
        <origin rpy="0 1.57075 0" xyz="0.1 0 0"/>
    </collision>
    <inertial>
      <mass value="0.05"/>
      <inertia ixx="1e-3" ixy="0.0" ixz="0.0" iyy="1e-3" iyz="0.0" izz="1e-3"/> 
    </inertial>
  </link>
  <joint name="base_link_gripper_extension" type="prismatic">
    <limit effort="1000.0" lower="-0.38" upper="0" velocity="0.5"/>
    <parent link="base_link"/>
    <child link="gripper_pole"/>
    <origin rpy="0 0 0" xyz="0.2 0 0.27"/>
  </joint>
  <link name="left_gripper">
    <visual>
        <geometry>
          <mesh filename="package://URDF/meshes/l_finger.dae"/>
        </geometry>
    </visual>
    <collision>
        <geometry>
          <mesh filename="package://URDF/meshes/l_finger.dae"/>
        </geometry>    
    </collision>
    <inertial>
      <mass value="0.05"/>
      <inertia ixx="1e-3" ixy="0.0" ixz="0.0" iyy="1e-3" iyz="0.0" izz="1e-3"/>    
    </inertial>
  </link>
  <joint name="left_gripper_gripper_pole" type="revolute">
    <axis rpy="0 0 0" xyz="0 0 1"/>
    <limit effort="1000.0" lower="0.0" upper="0.548" velocity="0.5"/>
    <parent link="gripper_pole"/>
    <child link="left_gripper"/>
    <origin rpy="0 0 0" xyz="0.19 0 0"/>
  </joint>
  <link name="gripper_tip">
    <visual>
        <geometry>
          <mesh filename="package://URDF/meshes/l_finger_tip.dae"/>
        </geometry>
        <origin rpy="-3.14 3.14 0" xyz="0 0 0"/>
    </visual>
    <collision>
        <geometry>
          <mesh filename="package://URDF/meshes/l_finger_tip.dae"/>
        </geometry>
        <origin rpy="-3.14 3.14 0" xyz="0 0 0"/>
    </collision>
    <inertial>
      <mass value="0.05"/>
      <inertia ixx="1e-3" ixy="0.0" ixz="0.0" iyy="1e-3" iyz="0.0" izz="1e-3"/>   
    </inertial>
  </link>
  <joint name="gripper_tip_gripper_pole" type="fixed">
    <parent link="gripper_pole"/>
    <child link="gripper_tip"/>
    <origin rpy="0 0 0" xyz="0.19 0 0"/>-->
  </joint>
  <link name="right_gripper">
    <visual>
        <geometry>
          <mesh filename="package://URDF/meshes/l_finger.dae"/>
        </geometry>
        <origin rpy="-3.1425 0 0" xyz="0 0 0"/>
    </visual>
    <collision>
        <geometry>
          <mesh filename="package://URDF/meshes/l_finger.dae"/>
        </geometry>
        <origin rpy="-3.1425 0 0" xyz="0 0 0"/>   
    </collision>
    <inertial>
      <mass value="0.05"/>
      <inertia ixx="1e-3" ixy="0.0" ixz="0.0" iyy="1e-3" iyz="0.0" izz="1e-3"/>   
    </inertial>
  </link>
  <joint name="right_gripper_gripper_pole" type="revolute">
    <axis rpy="0 0 0" xyz="0 0 -1"/>
    <limit effort="1000.0" lower="0.0" upper="0.548" velocity="0.5"/>
    <parent link="gripper_pole"/>
    <child link="right_gripper"/>
    <origin rpy="0 0 0" xyz="0.19 0 0"/>
  </joint>
  <link name="head">
    <visual>
        <geometry>
          <sphere radius="0.2"/>
        </geometry>
        <material name="wite"/>
    </visual>
    <collision>
        <geometry>
          <sphere radius="0.2"/>
        </geometry>
    </collision>
    <inertial>
      <mass value="1"/>
      <inertia ixx="1e-3" ixy="0.0" ixz="0.0" iyy="1e-3" iyz="0.0" izz="1e-3"/>   
    </inertial>
  </link>
  <joint name="head_base_link" type="continuous">
    <axis rpy="" xyz="0 0 1"/>
    <parent link="base_link"/>
    <child link="head"/>
    <axis xyz="0 0 1"/>
    <origin xyz="0 0 0.3"/>
  </joint>
  <link name="box">
    <visual>
        <geometry>
          <box size="0.08 0.08 0.08"/>
        </geometry>
        <material name="blue"/>
    </visual>
    <collision>
        <geometry>
          <box size="0.08 0.08 0.08"/>
        </geometry>
    </collision>
    <inertial>
      <mass value="1"/>
      <inertia ixx="1e-3" ixy="0.0" ixz="0.0" iyy="1e-3" iyz="0.0" izz="1e-3"/>   
    </inertial>
  </link>
  <joint name="box_head" type="fixed">
    <parent link="head"/>
    <child link="box"/>
    <origin xyz="0.15 0 0.14"/>
  </joint>

</robot>